Workbook

Sheet Read me
A1: Disproportionality and registry O/E calculator
A2: Signal Management in Medical Device Vigilance · Selim Medical Press · © 2026 · Tool T-7 · Chapter 9 (section 9.5; Tables 9.1–9.3)
A3: Educational template — adapt to your quality system. Not a regulatory requirement. All example data are fictional.
A5: Purpose
A6: Sheet 1 (2×2) takes the four cells of a 2×2 table and returns PRR and ROR with log-method confidence intervals, the expected count, the Yates chi-square and a screening flag against the company's documented rule. Sheet 2 (O-E) takes observed and expected counts and returns O/E with an exact Poisson confidence interval, the one-sided probability, and exact funnel limits at 95% and 99.8%, with a funnel plot.
A7: When to use
A8: When a spontaneous-report database (AEMS, which absorbed the former MAUDE database) or a registry is part of detection or assessment. Each sheet ends with interpretation prompts that must be answered in words before the result is filed.
A9: Sheets
A10: 2x2 Example — Glucalyn (fictional): a = 30, b = 570, c = 90, d = 8,910. Reproduces PRR 5.0 (3.34–7.50), ROR 5.21 (3.42–7.94), expected 7.5, chi-square 69.7.
A11: O-E Example — Tessora (fictional): O = 48, E = 26.0. Reproduces O/E 1.85 (1.36–2.45) and exact 99.8% limits 12 to 43 at E = 26.
A12: 2x2 Your data and O-E Your data — blank calculators. Summary — Table 9.3 with a column for your entries, and Table 9.2.
A13: Formulas
... A19: Companion web tool: https://abdu94-hash.github.io/device-signal-tool/

Sheet 2x2 Example
A1: Disproportionality: 2×2 table, PRR and ROR — Example (Glucalyn, fictional)
A2: Signal Management in Medical Device Vigilance · Selim Medical Press · © 2026 · Tool T-7 · Chapter 9
A3: Educational template — adapt to your quality system. Not a regulatory requirement. All example data are fictional.
A4: Legend: | B4: Input (edit) | C4: Calculated (do not edit)
A6: Source and data cut | B6: MAUDE-era extract, one product code, Year 2, month 12
A7: Event of interest | B7: Occlusion-related delivery problem
A9: 2×2 table | B9: Event of interest | C9: All other events / reports | D9: Total
A10: Device of interest (Glucalyn) | B10: 30 | C10: 570 | D10: =IF(COUNT(B10:C10)<2,"",B10+C10) | F10: a = B10, b = C10
A11: All other devices in the comparator set (other pumps, same product code) | B11: 90 | C11: 8910 | D11: =IF(COUNT(B11:C11)<2,"",B11+C11) | F11: c = B11, d = C11
A12: Total | B12: =IF(COUNT(B10:B11)<2,"",B10+B11) | C12: =IF(COUNT(C10:C11)<2,"",C10+C11) | D12: =IF(COUNT(B10:C11)<4,"",SUM(B10:C11))
A14: SETTINGS
A15: Confidence level | B15: 0.95
A16: z for the confidence level | B16: =_xlfn.NORM.S.INV(1-(1-B15)/2)
A17: Screening rule (company example): minimum PRR | B17: 2
A18: Screening rule: minimum chi-square (Yates) | B18: 4
A19: Screening rule: minimum number of cases (a) | B19: 3
A21: RESULTS
A22: Statistic | B22: Estimate | C22: Lower CI | D22: Upper CI
A23: PRR = [a ÷ (a + b)] ÷ [c ÷ (c + d)] | B23: =IF(OR(COUNT($B$10:$C$11)<4,MIN($B$10:$C$11)<=0),"",(B10/D10)/(B11/D11)) | C23: =IF(OR(COUNT($B$10:$C$11)<4,MIN($B$10:$C$11)<=0),"",EXP(LN(B23)-$B$16*B24)) | D23: =IF(OR(COUNT($B$10:$C$11)<4,MIN($B$10:$C$11)<=0),"",EXP(LN(B23)+$B$16*B24)) | F23: Book: PRR 5.0 (3.34–7.50)
A24: SE of ln(PRR) = √(1/a − 1/(a+b) + 1/c − 1/(c+d)) | B24: =IF(OR(COUNT($B$10:$C$11)<4,MIN($B$10:$C$11)<=0),"",SQRT(1/B10-1/D10+1/B11-1/D11))
A25: ROR = (a × d) ÷ (b × c) | B25: =IF(OR(COUNT($B$10:$C$11)<4,MIN($B$10:$C$11)<=0),"",(B10*C11)/(C10*B11)) | C25: =IF(OR(COUNT($B$10:$C$11)<4,MIN($B$10:$C$11)<=0),"",EXP(LN(B25)-$B$16*B26)) | D25: =IF(OR(COUNT($B$10:$C$11)<4,MIN($B$10:$C$11)<=0),"",EXP(LN(B25)+$B$16*B26)) | F25: Book: ROR 5.21 (3.42–7.94)
A26: SE of ln(ROR) = √(1/a + 1/b + 1/c + 1/d) | B26: =IF(OR(COUNT($B$10:$C$11)<4,MIN($B$10:$C$11)<=0),"",SQRT(1/B10+1/C10+1/B11+1/C11))
A27: Expected count in cell a = (a + b) × (a + c) ÷ N | B27: =IF(OR(COUNT($B$10:$C$11)<4,MIN($B$10:$C$11)<=0),"",D10*B12/D12) | F27: Book: 7.5 expected
A28: Observed ÷ expected (cell a) | B28: =IF(OR(COUNT($B$10:$C$11)<4,MIN($B$10:$C$11)<=0),"",B10/B27)
A29: Chi-square with Yates correction = N × (|ad − bc| − N/2)² ÷ [(a+b)(c+d)(a+c)(b+d)] | B29: =IF(OR(COUNT($B$10:$C$11)<4,MIN($B$10:$C$11)<=0),"",D12*(ABS(B10*C11-C10*B11)-D12/2)^2/(D10*D11*B12*C12)) | F29: Book: 69.7
A30: Screening flag against the documented rule | B30: =IF(OR(COUNT($B$10:$C$11)<4,MIN($B$10:$C$11)<=0),"",IF(AND(B23>=B17,B29>=B18,B10>=B19),"Rule met","Rule not met"))
A32: INTERPRETATION PROMPTS — answer in words before the result is filed
A33: What population, product code and data cut does the table describe? | B33: One product code; MAUDE-era data to Year 2, month 12.
A34: What can this ratio not show (rate, risk, version, cross-brand ranking)? | B34: No denominator; software version rarely stated in narratives, so v3.2 cannot be separated from v3.1.
A35: Known biases (stimulated reporting, coding, duplicates, summary reports)? | B35: Reporting stimulated by the company's own FSCA.
A36: What does it point to, and what is the next step? | B36: Brand-level excess; rely on version-level rates (rate ratio 13.5) and bench work.
A37: Reviewer and date

Sheet 2x2 Your data
A1: Disproportionality: 2×2 table, PRR and ROR — Your data
A2: Signal Management in Medical Device Vigilance · Selim Medical Press · © 2026 · Tool T-7 · Chapter 9
A3: Educational template — adapt to your quality system. Not a regulatory requirement. All example data are fictional.
A4: Legend: | B4: Input (edit) | C4: Calculated (do not edit)
A6: Source and data cut
A7: Event of interest
A9: 2×2 table | B9: Event of interest | C9: All other events / reports | D9: Total
A10: Device of interest | D10: =IF(COUNT(B10:C10)<2,"",B10+C10) | F10: a = B10, b = C10
A11: All other devices in the comparator set | D11: =IF(COUNT(B11:C11)<2,"",B11+C11) | F11: c = B11, d = C11
A12: Total | B12: =IF(COUNT(B10:B11)<2,"",B10+B11) | C12: =IF(COUNT(C10:C11)<2,"",C10+C11) | D12: =IF(COUNT(B10:C11)<4,"",SUM(B10:C11))
A14: SETTINGS
A15: Confidence level | B15: 0.95
A16: z for the confidence level | B16: =_xlfn.NORM.S.INV(1-(1-B15)/2)
A17: Screening rule (company example): minimum PRR | B17: 2
A18: Screening rule: minimum chi-square (Yates) | B18: 4
A19: Screening rule: minimum number of cases (a) | B19: 3
A21: RESULTS
A22: Statistic | B22: Estimate | C22: Lower CI | D22: Upper CI
A23: PRR = [a ÷ (a + b)] ÷ [c ÷ (c + d)] | B23: =IF(OR(COUNT($B$10:$C$11)<4,MIN($B$10:$C$11)<=0),"",(B10/D10)/(B11/D11)) | C23: =IF(OR(COUNT($B$10:$C$11)<4,MIN($B$10:$C$11)<=0),"",EXP(LN(B23)-$B$16*B24)) | D23: =IF(OR(COUNT($B$10:$C$11)<4,MIN($B$10:$C$11)<=0),"",EXP(LN(B23)+$B$16*B24))
A24: SE of ln(PRR) = √(1/a − 1/(a+b) + 1/c − 1/(c+d)) | B24: =IF(OR(COUNT($B$10:$C$11)<4,MIN($B$10:$C$11)<=0),"",SQRT(1/B10-1/D10+1/B11-1/D11))
A25: ROR = (a × d) ÷ (b × c) | B25: =IF(OR(COUNT($B$10:$C$11)<4,MIN($B$10:$C$11)<=0),"",(B10*C11)/(C10*B11)) | C25: =IF(OR(COUNT($B$10:$C$11)<4,MIN($B$10:$C$11)<=0),"",EXP(LN(B25)-$B$16*B26)) | D25: =IF(OR(COUNT($B$10:$C$11)<4,MIN($B$10:$C$11)<=0),"",EXP(LN(B25)+$B$16*B26))
A26: SE of ln(ROR) = √(1/a + 1/b + 1/c + 1/d) | B26: =IF(OR(COUNT($B$10:$C$11)<4,MIN($B$10:$C$11)<=0),"",SQRT(1/B10+1/C10+1/B11+1/C11))
A27: Expected count in cell a = (a + b) × (a + c) ÷ N | B27: =IF(OR(COUNT($B$10:$C$11)<4,MIN($B$10:$C$11)<=0),"",D10*B12/D12)
A28: Observed ÷ expected (cell a) | B28: =IF(OR(COUNT($B$10:$C$11)<4,MIN($B$10:$C$11)<=0),"",B10/B27)
A29: Chi-square with Yates correction = N × (|ad − bc| − N/2)² ÷ [(a+b)(c+d)(a+c)(b+d)] | B29: =IF(OR(COUNT($B$10:$C$11)<4,MIN($B$10:$C$11)<=0),"",D12*(ABS(B10*C11-C10*B11)-D12/2)^2/(D10*D11*B12*C12))
A30: Screening flag against the documented rule | B30: =IF(OR(COUNT($B$10:$C$11)<4,MIN($B$10:$C$11)<=0),"",IF(AND(B23>=B17,B29>=B18,B10>=B19),"Rule met","Rule not met"))
A32: INTERPRETATION PROMPTS — answer in words before the result is filed
A33: What population, product code and data cut does the table describe?
A34: What can this ratio not show (rate, risk, version, cross-brand ranking)?
A35: Known biases (stimulated reporting, coding, duplicates, summary reports)?
A36: What does it point to, and what is the next step?
A37: Reviewer and date

Sheet O-E Example
A1: Registry observed ÷ expected and exact Poisson funnel limits — Example (Tessora, fictional)
A2: Signal Management in Medical Device Vigilance · Selim Medical Press · © 2026 · Tool T-7 · Chapter 9
A3: Educational template — adapt to your quality system. Not a regulatory requirement. All example data are fictional.
A4: Legend: | B4: Input (edit) | C4: Calculated (do not edit)
A6: Source and data cut | B6: National registry annual report, Year 6; 6,000 primary THAs
A7: Observed events O (e.g., revisions) | B7: 48
A8: Expected events E (case-mix adjusted) | B8: 26
A9: Confidence level for O/E | B9: 0.95
A10: Funnel limit 1 (two-sided coverage) | B10: 0.95
A11: Funnel limit 2 (two-sided coverage) | B11: 0.998
A13: RESULTS
A14: Statistic | B14: Estimate | C14: Lower | D14: Upper
A15: O/E, exact Poisson CI via CHISQ.INV: lower = χ²(α/2, 2O)/2 ÷ E; upper = χ²(1−α/2, 2O+2)/2 ÷ E | B15: =IF(OR($B$7="",$B$8="",N($B$8)<=0),"",B7/B8) | C15: =IF(OR($B$7="",$B$8="",N($B$8)<=0),"",IF(B7=0,0,_xlfn.CHISQ.INV((1-B9)/2,2*B7)/2)/B8) | D15: =IF(OR($B$7="",$B$8="",N($B$8)<=0),"",_xlfn.CHISQ.INV(1-(1-B9)/2,2*B7+2)/2/B8) | H15: Book: O/E 1.85 (1.36–2.45)
A16: Cross-check via GAMMA.INV: lower = Γ⁻¹(α/2; O, 1) ÷ E; upper = Γ⁻¹(1−α/2; O+1, 1) ÷ E | B16: =IF(OR($B$7="",$B$8="",N($B$8)<=0),"",B7/B8) | C16: =IF(OR($B$7="",$B$8="",N($B$8)<=0),"",IF(B7=0,0,_xlfn.GAMMA.INV((1-B9)/2,B7,1))/B8) | D16: =IF(OR($B$7="",$B$8="",N($B$8)<=0),"",_xlfn.GAMMA.INV(1-(1-B9)/2,B7+1,1)/B8)
A17: Excess events = O − E | B17: =IF(OR($B$7="",$B$8="",N($B$8)<=0),"",B7-B8)
A18: One-sided P(X ≥ O | E) = 1 − POISSON.DIST(O − 1, E, TRUE) | B18: =IF(OR($B$7="",$B$8="",N($B$8)<=0),"",IF(B7=0,1,1-_xlfn.POISSON.DIST(B7-1,B8,TRUE))) | H18: Book: about 0.00007
A20: FUNNEL LIMITS AT THIS E (exact Poisson quantiles: smallest x with P(X ≤ x) ≥ p)
A21: Limit | B21: Lower limit (count) | C21: Upper limit (count) | D21: O above upper? | E21: O below lower?
A22: =TEXT(B10,"0.0%")&" limits" | B22: =IF(OR($B$7="",$B$8="",N($B$8)<=0),"",SUMPRODUCT(--(_xlfn.POISSON.DIST(x_helper!$A$2:$A$5001,$B$8,TRUE)<(1-B10)/2))) | C22: =IF(OR($B$7="",$B$8="",N($B$8)<=0),"",SUMPRODUCT(--(_xlfn.POISSON.DIST(x_helper!$A$2:$A$5001,$B$8,TRUE)<1-(1-B10)/2))) | D22: =IF(OR($B$7="",$B$8="",N($B$8)<=0),"",IF(B7>C22,"Yes","No")) | E22: =IF(OR($B$7="",$B$8="",N($B$8)<=0),"",IF(B7<B22,"Yes","No")) | H22: Book: 17 to 36 at 95%
A23: =TEXT(B11,"0.0%")&" limits" | B23: =IF(OR($B$7="",$B$8="",N($B$8)<=0),"",SUMPRODUCT(--(_xlfn.POISSON.DIST(x_helper!$A$2:$A$5001,$B$8,TRUE)<(1-B11)/2))) | C23: =IF(OR($B$7="",$B$8="",N($B$8)<=0),"",SUMPRODUCT(--(_xlfn.POISSON.DIST(x_helper!$A$2:$A$5001,$B$8,TRUE)<1-(1-B11)/2))) | D23: =IF(OR($B$7="",$B$8="",N($B$8)<=0),"",IF(B7>C23,"Yes","No")) | E23: =IF(OR($B$7="",$B$8="",N($B$8)<=0),"",IF(B7<B23,"Yes","No")) | H23: Book: 12 to 43 at 99.8%; 48 lies above
A24: Normal approximation, upper limit 2 = E + z × √E (for comparison only) | C24: =IF(OR($B$7="",$B$8="",N($B$8)<=0),"",B8+_xlfn.NORM.S.INV(1-(1-B11)/2)*SQRT(B8)) | H24: Book: 41.8 (rounds to 42)
A25: Position on the funnel | B25: =IF(OR($B$7="",$B$8="",N($B$8)<=0),"",IF(B7>C23,"Above the "&TEXT(B11,"0.0%")&" upper limit",IF(B7>C22,"Above the "&TEXT(B10,"0.0%")&" upper limit only",IF(B7<B23,"Below the "&TEXT(B11,"0.0%")&" lower limit",IF(B7<B22,"Below the "&TEXT(B10,"0.0%")&" lower limit only","Within the "&TEXT(B10,"0.0%")&" limits")))))
A27: FUNNEL TABLE (edit the expected counts in column A to suit your registry)
A28: Expected E | B28: Lower limit 1 | C28: Upper limit 1 | D28: Lower limit 2 | E28: Upper limit 2 | F28: Your unit: O (at its E)
A29: 2 | B29: =IF(A29="","",SUMPRODUCT(--(_xlfn.POISSON.DIST(x_helper!$A$2:$A$5001,A29,TRUE)<(1-$B$10)/2))) | C29: =IF(A29="","",SUMPRODUCT(--(_xlfn.POISSON.DIST(x_helper!$A$2:$A$5001,A29,TRUE)<1-(1-$B$10)/2))) | D29: =IF(A29="","",SUMPRODUCT(--(_xlfn.POISSON.DIST(x_helper!$A$2:$A$5001,A29,TRUE)<(1-$B$11)/2))) | E29: =IF(A29="","",SUMPRODUCT(--(_xlfn.POISSON.DIST(x_helper!$A$2:$A$5001,A29,TRUE)<1-(1-$B$11)/2)))
A30: 5 | B30: =IF(A30="","",SUMPRODUCT(--(_xlfn.POISSON.DIST(x_helper!$A$2:$A$5001,A30,TRUE)<(1-$B$10)/2))) | C30: =IF(A30="","",SUMPRODUCT(--(_xlfn.POISSON.DIST(x_helper!$A$2:$A$5001,A30,TRUE)<1-(1-$B$10)/2))) | D30: =IF(A30="","",SUMPRODUCT(--(_xlfn.POISSON.DIST(x_helper!$A$2:$A$5001,A30,TRUE)<(1-$B$11)/2))) | E30: =IF(A30="","",SUMPRODUCT(--(_xlfn.POISSON.DIST(x_helper!$A$2:$A$5001,A30,TRUE)<1-(1-$B$11)/2)))
A31: 10 | B31: =IF(A31="","",SUMPRODUCT(--(_xlfn.POISSON.DIST(x_helper!$A$2:$A$5001,A31,TRUE)<(1-$B$10)/2))) | C31: =IF(A31="","",SUMPRODUCT(--(_xlfn.POISSON.DIST(x_helper!$A$2:$A$5001,A31,TRUE)<1-(1-$B$10)/2))) | D31: =IF(A31="","",SUMPRODUCT(--(_xlfn.POISSON.DIST(x_helper!$A$2:$A$5001,A31,TRUE)<(1-$B$11)/2))) | E31: =IF(A31="","",SUMPRODUCT(--(_xlfn.POISSON.DIST(x_helper!$A$2:$A$5001,A31,TRUE)<1-(1-$B$11)/2)))
A32: 15 | B32: =IF(A32="","",SUMPRODUCT(--(_xlfn.POISSON.DIST(x_helper!$A$2:$A$5001,A32,TRUE)<(1-$B$10)/2))) | C32: =IF(A32="","",SUMPRODUCT(--(_xlfn.POISSON.DIST(x_helper!$A$2:$A$5001,A32,TRUE)<1-(1-$B$10)/2))) | D32: =IF(A32="","",SUMPRODUCT(--(_xlfn.POISSON.DIST(x_helper!$A$2:$A$5001,A32,TRUE)<(1-$B$11)/2))) | E32: =IF(A32="","",SUMPRODUCT(--(_xlfn.POISSON.DIST(x_helper!$A$2:$A$5001,A32,TRUE)<1-(1-$B$11)/2)))
A33: 20 | B33: =IF(A33="","",SUMPRODUCT(--(_xlfn.POISSON.DIST(x_helper!$A$2:$A$5001,A33,TRUE)<(1-$B$10)/2))) | C33: =IF(A33="","",SUMPRODUCT(--(_xlfn.POISSON.DIST(x_helper!$A$2:$A$5001,A33,TRUE)<1-(1-$B$10)/2))) | D33: =IF(A33="","",SUMPRODUCT(--(_xlfn.POISSON.DIST(x_helper!$A$2:$A$5001,A33,TRUE)<(1-$B$11)/2))) | E33: =IF(A33="","",SUMPRODUCT(--(_xlfn.POISSON.DIST(x_helper!$A$2:$A$5001,A33,TRUE)<1-(1-$B$11)/2)))
A34: 26 | B34: =IF(A34="","",SUMPRODUCT(--(_xlfn.POISSON.DIST(x_helper!$A$2:$A$5001,A34,TRUE)<(1-$B$10)/2))) | C34: =IF(A34="","",SUMPRODUCT(--(_xlfn.POISSON.DIST(x_helper!$A$2:$A$5001,A34,TRUE)<1-(1-$B$10)/2))) | D34: =IF(A34="","",SUMPRODUCT(--(_xlfn.POISSON.DIST(x_helper!$A$2:$A$5001,A34,TRUE)<(1-$B$11)/2))) | E34: =IF(A34="","",SUMPRODUCT(--(_xlfn.POISSON.DIST(x_helper!$A$2:$A$5001,A34,TRUE)<1-(1-$B$11)/2)))
A35: 30 | B35: =IF(A35="","",SUMPRODUCT(--(_xlfn.POISSON.DIST(x_helper!$A$2:$A$5001,A35,TRUE)<(1-$B$10)/2))) | C35: =IF(A35="","",SUMPRODUCT(--(_xlfn.POISSON.DIST(x_helper!$A$2:$A$5001,A35,TRUE)<1-(1-$B$10)/2))) | D35: =IF(A35="","",SUMPRODUCT(--(_xlfn.POISSON.DIST(x_helper!$A$2:$A$5001,A35,TRUE)<(1-$B$11)/2))) | E35: =IF(A35="","",SUMPRODUCT(--(_xlfn.POISSON.DIST(x_helper!$A$2:$A$5001,A35,TRUE)<1-(1-$B$11)/2)))
A36: 40 | B36: =IF(A36="","",SUMPRODUCT(--(_xlfn.POISSON.DIST(x_helper!$A$2:$A$5001,A36,TRUE)<(1-$B$10)/2))) | C36: =IF(A36="","",SUMPRODUCT(--(_xlfn.POISSON.DIST(x_helper!$A$2:$A$5001,A36,TRUE)<1-(1-$B$10)/2))) | D36: =IF(A36="","",SUMPRODUCT(--(_xlfn.POISSON.DIST(x_helper!$A$2:$A$5001,A36,TRUE)<(1-$B$11)/2))) | E36: =IF(A36="","",SUMPRODUCT(--(_xlfn.POISSON.DIST(x_helper!$A$2:$A$5001,A36,TRUE)<1-(1-$B$11)/2)))
A37: 50 | B37: =IF(A37="","",SUMPRODUCT(--(_xlfn.POISSON.DIST(x_helper!$A$2:$A$5001,A37,TRUE)<(1-$B$10)/2))) | C37: =IF(A37="","",SUMPRODUCT(--(_xlfn.POISSON.DIST(x_helper!$A$2:$A$5001,A37,TRUE)<1-(1-$B$10)/2))) | D37: =IF(A37="","",SUMPRODUCT(--(_xlfn.POISSON.DIST(x_helper!$A$2:$A$5001,A37,TRUE)<(1-$B$11)/2))) | E37: =IF(A37="","",SUMPRODUCT(--(_xlfn.POISSON.DIST(x_helper!$A$2:$A$5001,A37,TRUE)<1-(1-$B$11)/2)))
A38: 60 | B38: =IF(A38="","",SUMPRODUCT(--(_xlfn.POISSON.DIST(x_helper!$A$2:$A$5001,A38,TRUE)<(1-$B$10)/2))) | C38: =IF(A38="","",SUMPRODUCT(--(_xlfn.POISSON.DIST(x_helper!$A$2:$A$5001,A38,TRUE)<1-(1-$B$10)/2))) | D38: =IF(A38="","",SUMPRODUCT(--(_xlfn.POISSON.DIST(x_helper!$A$2:$A$5001,A38,TRUE)<(1-$B$11)/2))) | E38: =IF(A38="","",SUMPRODUCT(--(_xlfn.POISSON.DIST(x_helper!$A$2:$A$5001,A38,TRUE)<1-(1-$B$11)/2)))
A39: 80 | B39: =IF(A39="","",SUMPRODUCT(--(_xlfn.POISSON.DIST(x_helper!$A$2:$A$5001,A39,TRUE)<(1-$B$10)/2))) | C39: =IF(A39="","",SUMPRODUCT(--(_xlfn.POISSON.DIST(x_helper!$A$2:$A$5001,A39,TRUE)<1-(1-$B$10)/2))) | D39: =IF(A39="","",SUMPRODUCT(--(_xlfn.POISSON.DIST(x_helper!$A$2:$A$5001,A39,TRUE)<(1-$B$11)/2))) | E39: =IF(A39="","",SUMPRODUCT(--(_xlfn.POISSON.DIST(x_helper!$A$2:$A$5001,A39,TRUE)<1-(1-$B$11)/2)))
A40: 100 | B40: =IF(A40="","",SUMPRODUCT(--(_xlfn.POISSON.DIST(x_helper!$A$2:$A$5001,A40,TRUE)<(1-$B$10)/2))) | C40: =IF(A40="","",SUMPRODUCT(--(_xlfn.POISSON.DIST(x_helper!$A$2:$A$5001,A40,TRUE)<1-(1-$B$10)/2))) | D40: =IF(A40="","",SUMPRODUCT(--(_xlfn.POISSON.DIST(x_helper!$A$2:$A$5001,A40,TRUE)<(1-$B$11)/2))) | E40: =IF(A40="","",SUMPRODUCT(--(_xlfn.POISSON.DIST(x_helper!$A$2:$A$5001,A40,TRUE)<1-(1-$B$11)/2)))
... A42: 200 | B42: =IF(A42="","",SUMPRODUCT(--(_xlfn.POISSON.DIST(x_helper!$A$2:$A$5001,A42,TRUE)<(1-$B$10)/2))) | C42: =IF(A42="","",SUMPRODUCT(--(_xlfn.POISSON.DIST(x_helper!$A$2:$A$5001,A42,TRUE)<1-(1-$B$10)/2))) | D42: =IF(A42="","",SUMPRODUCT(--(_xlfn.POISSON.DIST(x_helper!$A$2:$A$5001,A42,TRUE)<(1-$B$11)/2))) | E42: =IF(A42="","",SUMPRODUCT(--(_xlfn.POISSON.DIST(x_helper!$A$2:$A$5001,A42,TRUE)<1-(1-$B$11)/2)))
A43: =IF($B$8="",NA(),$B$8) | F43: =IF(OR($B$7="",$B$8=""),NA(),$B$7) | G43: ← plotted point (shows the N/A error value while inputs are blank; intentional)
A45: INTERPRETATION PROMPTS — answer in words before the result is filed
A46: What case-mix variables does E adjust for, and what is left unadjusted? | B46: Case-mix adjustment limited to registry variables; center effects unchecked.
...

Sheet O-E Your data
A1: Registry observed ÷ expected and exact Poisson funnel limits — Your data
A2: Signal Management in Medical Device Vigilance · Selim Medical Press · © 2026 · Tool T-7 · Chapter 9
A3: Educational template — adapt to your quality system. Not a regulatory requirement. All example data are fictional.
A4: Legend: | B4: Input (edit) | C4: Calculated (do not edit)
A6: Source and data cut
A7: Observed events O (e.g., revisions)
A8: Expected events E (case-mix adjusted)
A9: Confidence level for O/E | B9: 0.95
A10: Funnel limit 1 (two-sided coverage) | B10: 0.95
A11: Funnel limit 2 (two-sided coverage) | B11: 0.998
A13: RESULTS
A14: Statistic | B14: Estimate | C14: Lower | D14: Upper
A15: O/E, exact Poisson CI via CHISQ.INV: lower = χ²(α/2, 2O)/2 ÷ E; upper = χ²(1−α/2, 2O+2)/2 ÷ E | B15: =IF(OR($B$7="",$B$8="",N($B$8)<=0),"",B7/B8) | C15: =IF(OR($B$7="",$B$8="",N($B$8)<=0),"",IF(B7=0,0,_xlfn.CHISQ.INV((1-B9)/2,2*B7)/2)/B8) | D15: =IF(OR($B$7="",$B$8="",N($B$8)<=0),"",_xlfn.CHISQ.INV(1-(1-B9)/2,2*B7+2)/2/B8)
A16: Cross-check via GAMMA.INV: lower = Γ⁻¹(α/2; O, 1) ÷ E; upper = Γ⁻¹(1−α/2; O+1, 1) ÷ E | B16: =IF(OR($B$7="",$B$8="",N($B$8)<=0),"",B7/B8) | C16: =IF(OR($B$7="",$B$8="",N($B$8)<=0),"",IF(B7=0,0,_xlfn.GAMMA.INV((1-B9)/2,B7,1))/B8) | D16: =IF(OR($B$7="",$B$8="",N($B$8)<=0),"",_xlfn.GAMMA.INV(1-(1-B9)/2,B7+1,1)/B8)
A17: Excess events = O − E | B17: =IF(OR($B$7="",$B$8="",N($B$8)<=0),"",B7-B8)
A18: One-sided P(X ≥ O | E) = 1 − POISSON.DIST(O − 1, E, TRUE) | B18: =IF(OR($B$7="",$B$8="",N($B$8)<=0),"",IF(B7=0,1,1-_xlfn.POISSON.DIST(B7-1,B8,TRUE)))
A20: FUNNEL LIMITS AT THIS E (exact Poisson quantiles: smallest x with P(X ≤ x) ≥ p)
A21: Limit | B21: Lower limit (count) | C21: Upper limit (count) | D21: O above upper? | E21: O below lower?
A22: =TEXT(B10,"0.0%")&" limits" | B22: =IF(OR($B$7="",$B$8="",N($B$8)<=0),"",SUMPRODUCT(--(_xlfn.POISSON.DIST(x_helper!$A$2:$A$5001,$B$8,TRUE)<(1-B10)/2))) | C22: =IF(OR($B$7="",$B$8="",N($B$8)<=0),"",SUMPRODUCT(--(_xlfn.POISSON.DIST(x_helper!$A$2:$A$5001,$B$8,TRUE)<1-(1-B10)/2))) | D22: =IF(OR($B$7="",$B$8="",N($B$8)<=0),"",IF(B7>C22,"Yes","No")) | E22: =IF(OR($B$7="",$B$8="",N($B$8)<=0),"",IF(B7<B22,"Yes","No"))
A23: =TEXT(B11,"0.0%")&" limits" | B23: =IF(OR($B$7="",$B$8="",N($B$8)<=0),"",SUMPRODUCT(--(_xlfn.POISSON.DIST(x_helper!$A$2:$A$5001,$B$8,TRUE)<(1-B11)/2))) | C23: =IF(OR($B$7="",$B$8="",N($B$8)<=0),"",SUMPRODUCT(--(_xlfn.POISSON.DIST(x_helper!$A$2:$A$5001,$B$8,TRUE)<1-(1-B11)/2))) | D23: =IF(OR($B$7="",$B$8="",N($B$8)<=0),"",IF(B7>C23,"Yes","No")) | E23: =IF(OR($B$7="",$B$8="",N($B$8)<=0),"",IF(B7<B23,"Yes","No"))
A24: Normal approximation, upper limit 2 = E + z × √E (for comparison only) | C24: =IF(OR($B$7="",$B$8="",N($B$8)<=0),"",B8+_xlfn.NORM.S.INV(1-(1-B11)/2)*SQRT(B8))
A25: Position on the funnel | B25: =IF(OR($B$7="",$B$8="",N($B$8)<=0),"",IF(B7>C23,"Above the "&TEXT(B11,"0.0%")&" upper limit",IF(B7>C22,"Above the "&TEXT(B10,"0.0%")&" upper limit only",IF(B7<B23,"Below the "&TEXT(B11,"0.0%")&" lower limit",IF(B7<B22,"Below the "&TEXT(B10,"0.0%")&" lower limit only","Within the "&TEXT(B10,"0.0%")&" limits")))))
A27: FUNNEL TABLE (edit the expected counts in column A to suit your registry)
A28: Expected E | B28: Lower limit 1 | C28: Upper limit 1 | D28: Lower limit 2 | E28: Upper limit 2 | F28: Your unit: O (at its E)
A29: 2 | B29: =IF(A29="","",SUMPRODUCT(--(_xlfn.POISSON.DIST(x_helper!$A$2:$A$5001,A29,TRUE)<(1-$B$10)/2))) | C29: =IF(A29="","",SUMPRODUCT(--(_xlfn.POISSON.DIST(x_helper!$A$2:$A$5001,A29,TRUE)<1-(1-$B$10)/2))) | D29: =IF(A29="","",SUMPRODUCT(--(_xlfn.POISSON.DIST(x_helper!$A$2:$A$5001,A29,TRUE)<(1-$B$11)/2))) | E29: =IF(A29="","",SUMPRODUCT(--(_xlfn.POISSON.DIST(x_helper!$A$2:$A$5001,A29,TRUE)<1-(1-$B$11)/2)))
A30: 5 | B30: =IF(A30="","",SUMPRODUCT(--(_xlfn.POISSON.DIST(x_helper!$A$2:$A$5001,A30,TRUE)<(1-$B$10)/2))) | C30: =IF(A30="","",SUMPRODUCT(--(_xlfn.POISSON.DIST(x_helper!$A$2:$A$5001,A30,TRUE)<1-(1-$B$10)/2))) | D30: =IF(A30="","",SUMPRODUCT(--(_xlfn.POISSON.DIST(x_helper!$A$2:$A$5001,A30,TRUE)<(1-$B$11)/2))) | E30: =IF(A30="","",SUMPRODUCT(--(_xlfn.POISSON.DIST(x_helper!$A$2:$A$5001,A30,TRUE)<1-(1-$B$11)/2)))
A31: 10 | B31: =IF(A31="","",SUMPRODUCT(--(_xlfn.POISSON.DIST(x_helper!$A$2:$A$5001,A31,TRUE)<(1-$B$10)/2))) | C31: =IF(A31="","",SUMPRODUCT(--(_xlfn.POISSON.DIST(x_helper!$A$2:$A$5001,A31,TRUE)<1-(1-$B$10)/2))) | D31: =IF(A31="","",SUMPRODUCT(--(_xlfn.POISSON.DIST(x_helper!$A$2:$A$5001,A31,TRUE)<(1-$B$11)/2))) | E31: =IF(A31="","",SUMPRODUCT(--(_xlfn.POISSON.DIST(x_helper!$A$2:$A$5001,A31,TRUE)<1-(1-$B$11)/2)))
A32: 15 | B32: =IF(A32="","",SUMPRODUCT(--(_xlfn.POISSON.DIST(x_helper!$A$2:$A$5001,A32,TRUE)<(1-$B$10)/2))) | C32: =IF(A32="","",SUMPRODUCT(--(_xlfn.POISSON.DIST(x_helper!$A$2:$A$5001,A32,TRUE)<1-(1-$B$10)/2))) | D32: =IF(A32="","",SUMPRODUCT(--(_xlfn.POISSON.DIST(x_helper!$A$2:$A$5001,A32,TRUE)<(1-$B$11)/2))) | E32: =IF(A32="","",SUMPRODUCT(--(_xlfn.POISSON.DIST(x_helper!$A$2:$A$5001,A32,TRUE)<1-(1-$B$11)/2)))
A33: 20 | B33: =IF(A33="","",SUMPRODUCT(--(_xlfn.POISSON.DIST(x_helper!$A$2:$A$5001,A33,TRUE)<(1-$B$10)/2))) | C33: =IF(A33="","",SUMPRODUCT(--(_xlfn.POISSON.DIST(x_helper!$A$2:$A$5001,A33,TRUE)<1-(1-$B$10)/2))) | D33: =IF(A33="","",SUMPRODUCT(--(_xlfn.POISSON.DIST(x_helper!$A$2:$A$5001,A33,TRUE)<(1-$B$11)/2))) | E33: =IF(A33="","",SUMPRODUCT(--(_xlfn.POISSON.DIST(x_helper!$A$2:$A$5001,A33,TRUE)<1-(1-$B$11)/2)))
A34: 26 | B34: =IF(A34="","",SUMPRODUCT(--(_xlfn.POISSON.DIST(x_helper!$A$2:$A$5001,A34,TRUE)<(1-$B$10)/2))) | C34: =IF(A34="","",SUMPRODUCT(--(_xlfn.POISSON.DIST(x_helper!$A$2:$A$5001,A34,TRUE)<1-(1-$B$10)/2))) | D34: =IF(A34="","",SUMPRODUCT(--(_xlfn.POISSON.DIST(x_helper!$A$2:$A$5001,A34,TRUE)<(1-$B$11)/2))) | E34: =IF(A34="","",SUMPRODUCT(--(_xlfn.POISSON.DIST(x_helper!$A$2:$A$5001,A34,TRUE)<1-(1-$B$11)/2)))
A35: 30 | B35: =IF(A35="","",SUMPRODUCT(--(_xlfn.POISSON.DIST(x_helper!$A$2:$A$5001,A35,TRUE)<(1-$B$10)/2))) | C35: =IF(A35="","",SUMPRODUCT(--(_xlfn.POISSON.DIST(x_helper!$A$2:$A$5001,A35,TRUE)<1-(1-$B$10)/2))) | D35: =IF(A35="","",SUMPRODUCT(--(_xlfn.POISSON.DIST(x_helper!$A$2:$A$5001,A35,TRUE)<(1-$B$11)/2))) | E35: =IF(A35="","",SUMPRODUCT(--(_xlfn.POISSON.DIST(x_helper!$A$2:$A$5001,A35,TRUE)<1-(1-$B$11)/2)))
A36: 40 | B36: =IF(A36="","",SUMPRODUCT(--(_xlfn.POISSON.DIST(x_helper!$A$2:$A$5001,A36,TRUE)<(1-$B$10)/2))) | C36: =IF(A36="","",SUMPRODUCT(--(_xlfn.POISSON.DIST(x_helper!$A$2:$A$5001,A36,TRUE)<1-(1-$B$10)/2))) | D36: =IF(A36="","",SUMPRODUCT(--(_xlfn.POISSON.DIST(x_helper!$A$2:$A$5001,A36,TRUE)<(1-$B$11)/2))) | E36: =IF(A36="","",SUMPRODUCT(--(_xlfn.POISSON.DIST(x_helper!$A$2:$A$5001,A36,TRUE)<1-(1-$B$11)/2)))
A37: 50 | B37: =IF(A37="","",SUMPRODUCT(--(_xlfn.POISSON.DIST(x_helper!$A$2:$A$5001,A37,TRUE)<(1-$B$10)/2))) | C37: =IF(A37="","",SUMPRODUCT(--(_xlfn.POISSON.DIST(x_helper!$A$2:$A$5001,A37,TRUE)<1-(1-$B$10)/2))) | D37: =IF(A37="","",SUMPRODUCT(--(_xlfn.POISSON.DIST(x_helper!$A$2:$A$5001,A37,TRUE)<(1-$B$11)/2))) | E37: =IF(A37="","",SUMPRODUCT(--(_xlfn.POISSON.DIST(x_helper!$A$2:$A$5001,A37,TRUE)<1-(1-$B$11)/2)))
A38: 60 | B38: =IF(A38="","",SUMPRODUCT(--(_xlfn.POISSON.DIST(x_helper!$A$2:$A$5001,A38,TRUE)<(1-$B$10)/2))) | C38: =IF(A38="","",SUMPRODUCT(--(_xlfn.POISSON.DIST(x_helper!$A$2:$A$5001,A38,TRUE)<1-(1-$B$10)/2))) | D38: =IF(A38="","",SUMPRODUCT(--(_xlfn.POISSON.DIST(x_helper!$A$2:$A$5001,A38,TRUE)<(1-$B$11)/2))) | E38: =IF(A38="","",SUMPRODUCT(--(_xlfn.POISSON.DIST(x_helper!$A$2:$A$5001,A38,TRUE)<1-(1-$B$11)/2)))
A39: 80 | B39: =IF(A39="","",SUMPRODUCT(--(_xlfn.POISSON.DIST(x_helper!$A$2:$A$5001,A39,TRUE)<(1-$B$10)/2))) | C39: =IF(A39="","",SUMPRODUCT(--(_xlfn.POISSON.DIST(x_helper!$A$2:$A$5001,A39,TRUE)<1-(1-$B$10)/2))) | D39: =IF(A39="","",SUMPRODUCT(--(_xlfn.POISSON.DIST(x_helper!$A$2:$A$5001,A39,TRUE)<(1-$B$11)/2))) | E39: =IF(A39="","",SUMPRODUCT(--(_xlfn.POISSON.DIST(x_helper!$A$2:$A$5001,A39,TRUE)<1-(1-$B$11)/2)))
A40: 100 | B40: =IF(A40="","",SUMPRODUCT(--(_xlfn.POISSON.DIST(x_helper!$A$2:$A$5001,A40,TRUE)<(1-$B$10)/2))) | C40: =IF(A40="","",SUMPRODUCT(--(_xlfn.POISSON.DIST(x_helper!$A$2:$A$5001,A40,TRUE)<1-(1-$B$10)/2))) | D40: =IF(A40="","",SUMPRODUCT(--(_xlfn.POISSON.DIST(x_helper!$A$2:$A$5001,A40,TRUE)<(1-$B$11)/2))) | E40: =IF(A40="","",SUMPRODUCT(--(_xlfn.POISSON.DIST(x_helper!$A$2:$A$5001,A40,TRUE)<1-(1-$B$11)/2)))
... A42: 200 | B42: =IF(A42="","",SUMPRODUCT(--(_xlfn.POISSON.DIST(x_helper!$A$2:$A$5001,A42,TRUE)<(1-$B$10)/2))) | C42: =IF(A42="","",SUMPRODUCT(--(_xlfn.POISSON.DIST(x_helper!$A$2:$A$5001,A42,TRUE)<1-(1-$B$10)/2))) | D42: =IF(A42="","",SUMPRODUCT(--(_xlfn.POISSON.DIST(x_helper!$A$2:$A$5001,A42,TRUE)<(1-$B$11)/2))) | E42: =IF(A42="","",SUMPRODUCT(--(_xlfn.POISSON.DIST(x_helper!$A$2:$A$5001,A42,TRUE)<1-(1-$B$11)/2)))
A43: =IF($B$8="",NA(),$B$8) | F43: =IF(OR($B$7="",$B$8=""),NA(),$B$7) | G43: ← plotted point (shows the N/A error value while inputs are blank; intentional)
A45: INTERPRETATION PROMPTS — answer in words before the result is filed
A46: What case-mix variables does E adjust for, and what is left unadjusted?
...

Sheet Summary
A1: Summary sheet — one line per statistic, in words
A2: Signal Management in Medical Device Vigilance · Selim Medical Press · © 2026 · Tool T-7 · Chapter 9 (Table 9.3)
A3: Educational template — adapt to your quality system. Not a regulatory requirement. All example data are fictional.
A5: Field | B5: Glucalyn entry (example) | C5: Tessora entry (example) | D5: Your entry
A6: Source and data cut | B6: MAUDE-era extract, one product code, Year 2, month 12 | C6: National registry annual report, Year 6
A7: Statistic and 95% CI | B7: PRR 5.0 (3.34–7.50); ROR 5.21 (3.42–7.94) | C7: O/E 1.85 (1.36–2.45)
A8: Threshold and method | B8: Company rule: PRR ≥ 2, chi-square ≥ 4, n ≥ 3 (met) | C8: Exact Poisson 99.8% limit 43 at E = 26 (exceeded by 48)
A9: Known biases | B9: No denominator; version rarely stated; reporting stimulated by own FSCA | C9: Case-mix adjustment limited to registry variables; center effects unchecked
A10: What it points to, next step | B10: Brand-level excess; rely on version-level rates and bench work | C10: Liner dissociation, size 52–54, post-change period; frame assessment question
A12: Table 9.3 of the book, filled for the two fictional cases (illustrative). The last row is the one reviewers read first; if it cannot be completed in plain words, the statistic is not ready to go into a signal record.
A14: What each method can and cannot support (Table 9.2)
A15: Method | B15: Can support | C15: Cannot support
A16: PRR and ROR in AEMS | B16: "This event is overrepresented in this device's reports" | C16: An event rate, a risk estimate, or a cross-brand safety ranking
A17: Bayesian shrinkage (IC, EBGM) | B17: Damping of ratios built on few reports | C17: Correction of stimulated, summary or coding bias
A18: Registry O/E with exact CI | B18: "More revisions than case mix predicts" | C18: The cause of the excess, or which sizes and lots drive it
A19: Funnel plot, 95% and 99.8% limits | B19: Placing one implant among its peers | C19: A verdict on surgeon or center effects
A20: Kaplan–Meier cumulative revision | B20: Revision probability over time, with censoring | C20: Unbiased long-term figures where death is common

Sheet x_helper
A1: x (0–4999): helper values for exact Poisson funnel limits. Do not edit.
A2: 0
A3: 1
A4: 2
A5: 3
A6: 4
A7: 5
A8: 6
A9: 7
A10: 8
A11: 9
A12: 10
A13: 11
... A5001: 4999
